Workbook

Sheet Overview
A2: Build Governance Platform implementation tracker
A4: Record | B4: Total | C4: Verified or recorded complete | D4: Remaining
A5: Requirements | B5: =COUNTA(Requirements!A6:A63) | C5: =COUNTIF(Requirements!L6:L63,"Verified") | D5: =B5-C5
A6: Acceptance cases | B6: =COUNTA(Acceptance!A6:A28) | C6: =COUNTIF(Acceptance!G6:G28,"Verified") | D6: =B6-C6
A7: Remediation findings | B7: =COUNTA(Remediation!A6:A12) | C7: =COUNTIF(Remediation!H6:H12,"Verified") | D7: =B7-C7
A8: Work packages | B8: =COUNTA('Work packages'!A6:A19) | C8: =COUNTIF('Work packages'!L6:L19,"Recorded complete") | D8: =B8-C8
A11: How to update
A12: 1 | B12: Assign owners and due dates in amber cells.
A13: 2 | B13: Record test result, evidence location and reviewer.
A14: 3 | B14: Verified counts require Pass, evidence and reviewer.
A15: 4 | B15: Package completion is a recorded status, not proof that dependencies or gates passed.
A16: 5 | B16: Keep conditional items visible; no automatic exclusions or approvals.
A18: Source | B18: Directive v1.2 unchanged. Blueprint v0.2 owner approved on 15 September 2026. See APR-001 in Section 9.
B19: Owner review approved; tests remain unverified. DEC01–11 need further inputs. DEC12 policy adopted; real imports require authorisation.

Sheet Requirements
A2: Requirements — Blueprint v0.2 Approved
A5: ID | B5: Area | C5: Requirement | D5: Directive source | E5: Package | F5: Acceptance | G5: Test ID | H5: Expected result | I5: Test result | J5: Evidence reference | K5: Reviewer | L5: Verification | M5: Assigned owner | N5: Due date | O5: Notes
A6: REQ-001 | B6: Identity | C6: Register organisations and verified users; create an explicit organisation membership before project access. | D6: Directive v1.2 §5.1, 5.4, 9 | E6: WP03 | F6: AC01 AC02 AC21 | G6: TST-001 | H6: A verified member reaches only their organisation; an unverified or unrelated account is denied. | I6: Pass | J6: commit deb3969 (WP03); explicit organisation membership created at registration; test_identity.py registration tests | L6: =IF(AND(I6="Pass",J6<>"",K6<>""),"Verified","Unverified")
A7: REQ-002 | B7: Identity | C7: Require MFA for approval authority and provide accessible setup and verified recovery without elevating rights. | D7: Directive v1.2 §5.4, 7.3 | E7: WP03 | F7: AC14 AC21 | G7: TST-002 | H7: An approver without MFA cannot submit; recovery restores access only after identity checks and MFA re-enrolment. | I7: Pass | J7: require_mfa dependency (app/deps.py) gates approval authority; BGP-F01 fix (b1fb402) made login session-bound to a real second-factor check, not an account flag; test_hardening.py MFA-session tests | K7: MiltonBello15 (PR#3, BGP-F01 fix -- APPROVED) | L7: =IF(AND(I7="Pass",J7<>"",K7<>""),"Verified","Unverified")
A8: REQ-003 | B8: Identity | C8: Resolve active tenant from authenticated server session; verify membership when switching organisations. | D8: Directive v1.2 §5.1 | E8: WP03 | F8: AC02 AC14 | G8: TST-003 | H8: Changing a URL, request body or cookie tenant claim cannot grant another tenant; expired membership denies access. | I8: Pass | J8: Active tenant resolved from server session (app/deps.py); org-bootstrap RLS-context-ordering bug in get_active_membership fixed PR#4 (ac7f0f1) | K8: MiltonBello15 (PR#4 -- APPROVED) | L8: =IF(AND(I8="Pass",J8<>"",K8<>""),"Verified","Unverified")
A9: REQ-004 | B9: Identity | C9: Enforce project membership and template role permissions at each service operation. | D9: Directive v1.2 §5.4 | E9: WP03 | F9: AC14 AC16 | G9: TST-004 | H9: Contributor, approver and assurance users receive only allowed reads and writes. | I9: Pass | J9: require_role()/membership checks enforced per router (backend/app/routers/*.py); RLS-backed tests across test_wp0*_tenant_isolation_rls.py | L9: =IF(AND(I9="Pass",J9<>"",K9<>""),"Verified","Unverified")
A10: REQ-005 | B10: Identity | C10: Record and show tenant-administrator access to projects outside their membership to the sponsor. | D10: Directive v1.2 §5.4 | E10: WP03 | F10: AC14 | G10: TST-005 | H10: The access event identifies actor, project and time and is visible to the sponsor. | I10: Pass | J10: GET /orgs/{tenant_id}/access-review (app/routers/orgs.py:232); test_access_review_lists_tenant_membership + test_access_review_requires_tenant_administrator_role | L10: =IF(AND(I10="Pass",J10<>"",K10<>""),"Verified","Unverified")
A11: REQ-006 | B11: Identity | C11: Enforce separation of duties; any permitted override records approved compensating review and independent reviewer. | D11: Directive v1.2 §5.4 | E11: WP07 | F11: AC14 | G11: TST-006 | H11: Self-only approval is rejected unless the scoped override is valid; an empty reviewer note cannot satisfy it. | I11: Pass | J11: Compensating review now created from the reviewer's own authenticated, MFA-verified session (BGP-F02 fix, b1fb402); preparer-set-from-ownership bypass closed by the follow-up fix (b8bb22a, PR#3): test_clearing_or_reassigning_ownership_cannot_defeat_separation_of_duties | K11: MiltonBello15 (PR#3, BGP-F02 + follow-up fix -- APPROVED) | L11: =IF(AND(I11="Pass",J11<>"",K11<>""),"Verified","Unverified")
A12: REQ-007 | B12: Tenancy | C12: Put tenant IDs on all owned rows and enforce PostgreSQL RLS through a restricted application role. | D12: Directive v1.2 §5.1 | E12: WP04 | F12: AC02 | G12: TST-007 | H12: Missing tenant context returns no owned records; application roles cannot bypass RLS or act as table owners. | I12: Pass | J12: tenant_id on every owned row; RLS migrations 0002 (WP04) and 0014 (org-bootstrap fix, PR#4); adversarial cross-tenant suite passing against real Postgres | L12: =IF(AND(I12="Pass",J12<>"",K12<>""),"Verified","Unverified")
A13: REQ-008 | B13: Tenancy | C13: Reset tenant context across pooled transactions and enforce isolation in workers, files, caches, search and exports. | D13: Directive v1.2 §5.1, 5.5 | E13: WP04 | F13: AC02 | G13: TST-008 | H13: Reuse a connection between two tenants and run mixed-tenant jobs; no data crosses boundaries. | I13: Pass | J13: SET LOCAL app.tenant_id reset per request (app/deps.py); pooled-connection tenant-reset test in test_tenant_isolation_rls.py | L13: =IF(AND(I13="Pass",J13<>"",K13<>""),"Verified","Unverified")
A14: REQ-009 | B14: Tenancy | C14: Run an adversarial cross-tenant suite as a blocking CI check and demonstrate detection of a seeded leak. | D14: Directive v1.2 §5.1, 12 | E14: WP04 | F14: AC02 | G14: TST-009 | H14: A deliberately weakened policy or service query causes the suite to fail; repaired code passes. | I14: Pass | J14: Adversarial cross-tenant suite is a real, currently-green, CI-blocking check -- confirmed live via gh run view on run 35670396664, 2026-09-24 | L14: =IF(AND(I14="Pass",J14<>"",K14<>""),"Verified","Unverified")
A15: REQ-010 | B15: Templates | C15: Version framework templates containing tracks, gates, classification, role, status, decision and applicability schemes. | D15: Directive v1.2 §5.2 | E15: WP05 | F15: AC09 AC13 | G15: TST-010 | H15: Three distinct framework fixtures represent expected classes, roles and gates without application code changes. | I15: Pass | J15: Template versioning in app/rule_engine.py + templates router; create/publish tested | L15: =IF(AND(I15="Pass",J15<>"",K15<>""),"Verified","Unverified")
A16: REQ-011 | B16: Templates | C16: Make published versions immutable; bind each project to one version and approve explicit migrations. | D16: Directive v1.2 §5.2 | E16: WP05 | F16: AC13 | G16: TST-011 | H16: Publishing v2 leaves a v1 project unchanged; migration logs impact, approver and both versions. | I16: Pass | J16: Publish-time immutability enforced; changing a published template creates a new version, tested | L16: =IF(AND(I16="Pass",J16<>"",K16<>""),"Verified","Unverified")
A17: REQ-012 | B17: Templates | C17: Provide guided authoring, fork, blank creation and schema-validated JSON import and export. | D17: Directive v1.2 §5.2, 7, 9 | E17: WP05 | F17: AC08 AC09 | G17: TST-012 | H17: A tenant builds and runs a template without JSON; malformed or unsupported imports explain the failing field. | I17: Partial | J17: fork_template/import_template (app/routers/templates.py:171,205) and create-blank are real, tested backend endpoints, but the guided-authoring UI (UI08) has no frontend page yet -- open as IPA02 in BGP_Implementation_Plan_Alignment_Findings_v1.0.docx | L17: =IF(AND(I17="Pass",J17<>"",K17<>""),"Verified","Unverified")
A18: REQ-013 | B18: Templates | C18: Restrict configurable rules to a versioned declarative vocabulary; prohibit executable code and invariant overrides. | D18: Directive v1.2 §5.2.1 | E18: WP05 | F18: AC09 | G18: TST-013 | H18: Rule validation rejects arbitrary expressions, unknown operators, cycles and attempts to disable audit or export. | I18: Pass | J18: app/rule_engine.py restricted to eq/in/all/any vocabulary only, no eval/exec, depth limit 5 | L18: =IF(AND(I18="Pass",J18<>"",K18<>""),"Verified","Unverified")
A19: REQ-014 | B19: Templates | C19: Include KenAddme only after licensing clearance; otherwise supply a neutral starter. | D19: Directive v1.2 §5.2, 9, 14 | E19: WP05 | F19: AC01 AC09 | G19: TST-014 | H19: Release manifest records template provenance and licensing decision; unresolved content is excluded. | I19: Pass | J19: No real KenAddme content used; 3 neutral fictional framework fixtures (fixtures/synthetic/frameworks/) per DEC03's still-open licensing gate | L19: =IF(AND(I19="Pass",J19<>"",K19<>""),"Verified","Unverified")
A20: REQ-015 | B20: Projects | C20: Create a project with name, template binding, class, owner and explicit members; seed applicable evidence. | D20: Directive v1.2 §2.4, 5.2, 9 | E20: WP06 | F20: AC01 | G20: TST-015 | H20: Creation commits project and required items together, or neither when seeding fails. | I20: Pass | J20: Atomic project seeding proven by test_seeding_failure_leaves_no_project_row (monkeypatches mid-seed failure, asserts zero rows persist) | L20: =IF(AND(I20="Pass",J20<>"",K20<>""),"Verified","Unverified")
A21: REQ-016 | B21: Projects | C21: Represent every routine and triggered gate review as a separate occurrence with due date and evidence snapshot. | D21: Directive v1.2 §5.2.1, 11 | E21: WP06 | F21: AC12 | G21: TST-016 | H21: Two routine reviews and a triggered review preserve separate evidence and decisions. | I21: Pass | J21: gate_occurrences table represents every routine/triggered review as its own row (WP06) | L21: =IF(AND(I21="Pass",J21<>"",K21<>""),"Verified","Unverified")
A22: REQ-017 | B22: Evidence | C22: Track evidence status, owner, due date, completion date and reference; retain immutable revisions and change attribution. | D22: Directive v1.2 §5.3, 5.5, 9 | E22: WP06 | F22: AC10 AC11 | G22: TST-017 | H22: Editing creates a new revision; prior actor, time and values remain available. | I22: Pass | J22: evidence_items track status/owner/due date/completion date/reference (WP06) | L22: =IF(AND(I22="Pass",J22<>"",K22<>""),"Verified","Unverified")
A23: REQ-018 | B23: Evidence | C23: Validate completion against the resulting record on every update; do not allow removal of required evidence while Complete. | D23: Directive v1.2 §5.3.2 | E23: WP06 | F23: AC11 | G23: TST-018 | H23: A patch clearing a mandatory reference from a completed item is rejected or explicitly transitions it out of Complete. | I23: Pass | J23: status=Complete+required+no-reference rejected at the API boundary, enforced and tested | L23: =IF(AND(I23="Pass",J23<>"",K23<>""),"Verified","Unverified")
A24: REQ-019 | B24: Evidence | C24: Bind approved evidence to source versions or hashes where available; disclose mutable-reference limitations. | D24: Directive v1.2 §5.3.1 | E24: WP06 | F24: AC04 AC10 | G24: TST-019 | H24: The approval manifest preserves exact local revision and available source version; an unversioned URL is labelled. | I24: Pass | J24: source_version/source_hash are explicit disclosed fields, never inferred; preserved through export/import re-hops per BGP-F04 fix (b1fb402) and follow-up fix (b8bb22a) | K24: MiltonBello15 (PR#3, BGP-F04 follow-up fix -- APPROVED) | L24: =IF(AND(I24="Pass",J24<>"",K24<>""),"Verified","Unverified")
A25: REQ-020 | B25: Exceptions | C25: Validate not-applicable classifications against rules and class floor; validate exceptions by authority, scope and expiry. | D25: Directive v1.2 §5.3.2 | E25: WP07 | F25: AC03 AC11 | G25: TST-020 | H25: A typed status alone cannot exclude an item; expired, revoked and unrelated exceptions are rejected. | I25: Pass | J25: Corrected 2026-09-24: the codebase's real mechanism for a not-applicable classification is an authority/scope/expiry-checked ExceptionRecord (app/routers/decisions.py), not a literal status string -- my first grep for the literal text "Not applicable" was the wrong search and produced a false negative. REQ-020's own verify text ("A typed status alone cannot exclude an item; expired, revoked and unrelated exceptions are rejected") is met: test_exception_excuses_a_hard_blocker_and_revocation_reinstates_it (pre-existing, revocation), test_exception_that_has_expired_over_time_no_longer_excuses_the_blocker (new, live expiry re-check) and test_exception_scoped_to_one_item_does_not_excuse_a_different_item (new, cross-item scoping). Both new tests independently verified 2026-09-24 to actually fail when the real check is removed, not just pass by coincidence. | L25: =IF(AND(I25="Pass",J25<>"",K25<>""),"Verified","Unverified")
A26: REQ-021 | B26: Exceptions | C26: Reassess affected gates when exceptions expire or evidence changes; preserve earlier decisions. | D26: Directive v1.2 §5.3.1, 5.3.2 | E26: WP07 | F26: AC10 AC11 | G26: TST-021 | H26: An expired exception changes current readiness and triggers reassessment without rewriting history. | I26: Pass | J26: Exception create/revoke endpoints re-check authority/scope/expiry live on every call (app/routers/decisions.py), never trusted from a stored status field alone | L26: =IF(AND(I26="Pass",J26<>"",K26<>""),"Verified","Unverified")
A27: REQ-022 | B27: Decisions | C27: Permit approval only with satisfied requirements; conditional approval needs allowed conditions, owner, deadline and activity limits. | D27: Directive v1.2 §5.3.2 | E27: WP07 | F27: AC03 AC11 | G27: TST-022 | H27: Missing deadline or unresolved critical blocker denies conditional approval and records the attempt. | I27: Partial | J27: Conditions are recorded and required before a conditional approval, but REQ-022's own 'activity limits' on what a conditionally-approved project can then do are not enforced -- an open gap named in the WP07 build notes since 2026-09-16 (TR04) | L27: =IF(AND(I27="Pass",J27<>"",K27<>""),"Verified","Unverified")
A28: REQ-023 | B28: Decisions | C28: Record decisions append-only with authenticated authority, server time, occurrence, template and evidence manifest. | D28: Directive v1.2 §5.3.1 | E28: WP07 | F28: AC04 AC10 | G28: TST-023 | H28: Requests cannot supply an authoritative actor or timestamp; resulting records include all required bindings. | I28: Pass | J28: decision_records is a SELECT+INSERT-only DB-role grant (not just a route-level check); test_wp07_tenant_isolation_rls.py proves UPDATE/DELETE both raise permission denied | L28: =IF(AND(I28="Pass",J28<>"",K28<>""),"Verified","Unverified")
A29: REQ-024 | B29: Decisions | C29: Recheck authority and reviewed revision atomically; prevent stale approval and duplicate retry decisions. | D29: Directive v1.2 §5.3.1 | E29: WP07 | F29: AC10 | G29: TST-024 | H29: Concurrent evidence or membership changes reject stale commits; repeated identical keys return one decision. | I29: Pass | J29: Corrected 2026-09-25: two of the three gaps this note claimed were false when checked against the actual code -- exception validity (_exception_is_currently_valid, lock=True from _compute_readiness) and compensating-reviewer authority (_check_separation_of_duties's two with_for_update() calls) were already locked, added by the same BGP-F03 follow-up commit (b8bb22a) this note itself cites, just not re-verified before writing 'not locked' here. The one real gap -- the ACTING decision-maker's own tenant-level Membership was checked once, unlocked, by app/deps.py's get_active_membership before the handler ran, never re-locked at commit time -- is now fixed: _require_decision_authority locks and rechecks it (same fixed lock order as the rest of this path). Proved with a new live-Postgres lock-blocking test (test_tenant_membership_lock_blocks_a_concurrent_writer, test_bgp_f03_decision_concurrency.py), same technique as the existing ProjectMembership/evidence-item proofs alongside it. All three of REQ-024's own verify-text clauses (evidence changes, membership changes, repeated idempotency keys) now hold with passing tests. Full suite green after the fix. | K29: MiltonBello15 (PR#3/#4, concurrency fixes -- APPROVED; gap remains beyond what those PRs fixed) | L29: =IF(AND(I29="Pass",J29<>"",K29<>""),"Verified","Unverified")
A30: REQ-025 | B30: Decisions | C30: Support superseding corrections only; record a reason and original-decision link. | D30: Directive v1.2 §5.3 | E30: WP07 | F30: AC04 AC12 | G30: TST-025 | H30: Every application role is denied UPDATE or DELETE of decisions; a new correction retains the original. | I30: Pass | J30: Superseding endpoint never mutates the original row; a reason is mandatory; original-decision reference preserved | L30: =IF(AND(I30="Pass",J30<>"",K30<>""),"Verified","Unverified")
A31: REQ-026 | B31: Integrity | C31: Detect privileged tampering using separately controlled verification material, with defined custody and verification frequency. | D31: Directive v1.2 §5.3.1 | E31: WP08 | F31: AC04 | G31: TST-026 | H31: Alter stored history in a controlled test; independent verification detects it within the approved interval. | I31: Pass | J31: integrity_checkpoints hash chain (WP08); the bgp_owner Postgres-superuser RLS-bypass bug was found and fixed the same session it was discovered | L31: =IF(AND(I31="Pass",J31<>"",K31<>""),"Verified","Unverified")
A32: REQ-027 | B32: Integrity | C32: Block approval acknowledgements for affected integrity failures, preserve evidence and trigger incident handling. | D32: Directive v1.2 §5.3.1 | E32: WP08 | F32: AC04 | G32: TST-027 | H32: Injected mismatch denies new acknowledgements in affected scope and produces an incident record. | I32: Pass | J32: An open integrity incident blocks new decisions project-wide, HTTP 423 (WP08) | L32: =IF(AND(I32="Pass",J32<>"",K32<>""),"Verified","Unverified")
A33: REQ-028 | B33: Recovery | C33: Meet zero acknowledged-decision loss within the approved failure envelope, including interpretation records. | D33: Directive v1.2 §10 | E33: WP08 | F33: AC07 | G33: TST-028 | H33: Fault tests reconcile all acknowledged IDs and associated manifests after supported failures. | I33: Not tested | J33: Only a local-atomicity fault test exists (crash-at-commit leaves zero partial rows). The review's own text is explicit this is 'not a node/zone/region durability proof', and DEC05 (the actual approved failure envelope) remains unresolved -- so REQ-028's specific claim (zero loss within the APPROVED envelope) cannot be marked Pass without an envelope to test against. | L33: =IF(AND(I33="Pass",J33<>"",K33<>""),"Verified","Unverified")
A34: REQ-029 | B34: Recovery | C34: Restore ordinary data with RPO at most one hour and service within eight hours; test quarterly in clean environments. | D34: Directive v1.2 §6, 10 | E34: WP08 | F34: AC07 | G34: TST-029 | H34: Restore drill measures latest recoverable ordinary write and service recovery including integrity reconciliation. | I34: Partial | J34: backend/scripts/restore_drill.py actually run against live bgp_dev with real numbers (backup 1.18s / restore 4.14s / 16-table reconciliation, 2026-09-17). Explicitly scoped as a local-prototype-only result, not proof of the approved envelope's RPO/RTO since DEC05 is still open. | L34: =IF(AND(I34="Pass",J34<>"",K34<>""),"Verified","Unverified")
A35: REQ-030 | B35: Export | C35: Provide complete open-format tenant export and lossless clean-instance re-import without privilege transfer. | D35: Directive v1.2 §5.3, 9, 12 | E35: WP09 | F35: AC05 | G35: TST-030 | H35: Compare record IDs, counts, revisions, hashes and relationships after import; imported actors do not receive live credentials. | I35: Pass | J35: Full evidence-revision history, source_id provenance across export/import hops, decision-manifest/compensating-review export -- fixed via BGP-F04 (b1fb402) and follow-up (b8bb22a, PR#3): test_unmatched_revision_author_and_timestamp_survive_reexport | K35: MiltonBello15 (PR#3 -- APPROVED) | L35: =IF(AND(I35="Pass",J35<>"",K35<>""),"Verified","Unverified")
A36: REQ-031 | B36: Export | C36: Keep own-data export, audit history and MFA available on all tiers, including billing disputes. | D36: Directive v1.2 §5.3, 8 | E36: WP09 | F36: AC05 AC14 | G36: TST-031 | H36: A read-only billing state permits authorised exports and history access but denies ordinary writes. | I36: Pass | J36: Any active project member can export their own data -- explicitly documented in app/routers/exports.py's own REQ-031 comment (line 443) and exercised by test_export_import.py | L36: =IF(AND(I36="Pass",J36<>"",K36<>""),"Verified","Unverified")
A37: REQ-032 | B37: Usability | C37: Provide role-specific My work with project, reason, deadline, state and a direct action. | D37: Directive v1.2 §7.1 | E37: WP10 | F37: AC16 | G37: TST-032 | H37: Each persona finds their assigned action while unrelated assignments stay hidden. | I37: Pass | J37: GET /my-work wraps each item with project_name/reason/direct_action (WP10); my_work.html real page (WP11-heading frontend increment) | L37: =IF(AND(I37="Pass",J37<>"",K37<>""),"Verified","Unverified")
A38: REQ-033 | B38: Usability | C38: Provide short guided forms, field examples, clear errors and reversible navigation without losing valid input. | D38: Directive v1.2 §7.1 | E38: WP10 | F38: AC17 | G38: TST-033 | H38: Back navigation and invalid fields preserve all valid responses. | I38: Pass | J38: Guided forms with plain 'Back to My work' links present in evidence_form.html, project_new.html, decide.html -- grep-confirmed 2026-09-24 | L38: =IF(AND(I38="Pass",J38<>"",K38<>""),"Verified","Unverified")
A39: REQ-034 | B39: Usability | C39: Save and resume drafts with truthful Saving, Saved and Not saved states under a declared shared-device policy. | D39: Directive v1.2 §7.2 | E39: WP10 | F39: AC18 | G39: TST-034 | H39: Interrupt a save and reload within the supported boundary; saved data returns and unsaved data is not misrepresented. | I39: Pass | J39: drafts table, save/resume with Saving/Saved/Not saved states (WP10), tested | L39: =IF(AND(I39="Pass",J39<>"",K39<>""),"Verified","Unverified")
A40: REQ-035 | B40: Usability | C40: Distinguish pending from confirmed approvals; retrieve outcome after timeout and handle concurrent edits explicitly. | D40: Directive v1.2 §7.2 | E40: WP10 | F40: AC18 | G40: TST-035 | H40: Drop the response after commit; recovery displays the existing decision without creating another. | I40: Pass | J40: Fixed 2026-09-25: decide_page (GET) now mints one idempotency key per render, embedded in a hidden form field; decide_submit (POST) uses that value instead of a fresh uuid.uuid4() per call, so resubmitting the identical rendered form after a dropped response replays the same key and decisions.py's existing idempotency match returns the already-recorded decision instead of a confusing 409. A re-render after a denial/error mints a fresh key so a genuinely different follow-up attempt is never blocked as 'used for a different request'. Proved by test_req035_decision_recovery.py (2 tests, live Postgres): resubmitting the identical form returns the same decision id, not a duplicate; a fresh page load mints a new key. Existing webapp decide tests (test_wp11_webapp_rls.py, test_wp13_webapp_new_pages.py) updated for the new required field and still pass. | L40: =IF(AND(I40="Pass",J40<>"",K40<>""),"Verified","Unverified")
A41: REQ-036 | B41: Usability | C41: Explain blockers in plain language and link to their corrective action without exposing restricted information. | D41: Directive v1.2 §7.1 | E41: WP10 | F41: AC19 | G41: TST-036 | H41: A newcomer identifies the missing item and reaches the permitted correction without external documentation. | I41: Pass | J41: blocker_explanations: plain-language reason + corrective-action API call per blocker (WP10 preview endpoint) | L41: =IF(AND(I41="Pass",J41<>"",K41<>""),"Verified","Unverified")
A42: REQ-037 | B42: Usability | C42: Show evidence, conditions and permitted progression in a deliberate approval confirmation summary. | D42: Directive v1.2 §7.3 | E42: WP10 | F42: AC20 | G42: TST-037 | H42: Users explain the action permitted before submitting; opening a page or email never approves anything. | I42: Pass | J42: Decision preview shows evidence, conditions and permitted_outcomes (every outcome current readiness would allow), WP10 | L42: =IF(AND(I42="Pass",J42<>"",K42<>""),"Verified","Unverified")
A43: REQ-038 | B43: Usability | C43: Support invitation landing, accessible MFA and recovery as part of the essential task journey. | D43: Directive v1.2 §7.3 | E43: WP03 | F43: AC21 | G43: TST-038 | H43: An invited user reaches the intended project after sign-in and can recover without a control bypass. | I43: Pass | J43: Fixed 2026-09-25: new GET/POST /ui/invitations/accept + invitation_accept.html. GET only ever renders (never accepts -- an accept is a deliberate POST, same GET/POST split as decide_page/decide_submit); a signed-out visitor sees sign-in/register links carrying next=<this URL> back to the landing page, wired through login/register/mfa-login-verify's own new next parameter (open-redirect-guarded via _safe_next, only /ui/ paths allowed) so completing sign-in returns them here instead of the generic org picker -- REQ-038's own verify text: 'reaches the intended project after sign-in'. Signed-in acceptance redirects straight to that org's my-work page. Expired/reused/wrong-email tokens render the landing page's own honest error, not a crash. Proved by test_req038_invitation_landing.py (3 tests, live Postgres): sign-out-then-register-via-next lands back on the invite and then on the org; GET never has a side effect (checked via /me/orgs before/after); a reused token shows the real error. | L43: =IF(AND(I43="Pass",J43<>"",K43<>""),"Verified","Unverified")
...

Sheet Acceptance
A2: Acceptance — Blueprint v0.2 Approved
A5: ID | B5: Directive acceptance criterion | C5: Requirements | D5: Result | E5: Evidence reference | F5: Reviewer | G5: Verification | H5: Notes
A6: AC01 | B6: A person who has never read a governance framework registers, selects a starting template, creates a project and records a first gate decision, unaided, within twenty minutes. | C6: REQ-001 REQ-014 REQ-015 REQ-041 | D6: Not tested | E6: REQ-001/014/015 pass, but REQ-041's 20-minute unaided onboarding has never been tested with a real participant | G6: =IF(AND(D6="Pass",E6<>"",F6<>""),"Verified","Unverified")
A7: AC02 | B7: The cross-tenant isolation suite passes with zero findings, and a deliberately planted violation fails the build. | C7: REQ-001 REQ-003 REQ-007 REQ-008 REQ-009 REQ-050 REQ-053 | D7: Partial | E7: Cross-tenant isolation suite passes with zero findings against real Postgres (REQ-001/003/007/008/009/053 all Pass); REQ-050 independent penetration testing has not been performed | G7: =IF(AND(D7="Pass",E7<>"",F7<>""),"Verified","Unverified")
A8: AC03 | B8: An attempt to approve with outstanding mandatory evidence or a critical blocker is refused and logged. Conditional approval requires an allowed condition, owner, deadline and explicit activity limits; invalid or expired exceptions cannot satisfy evidence requirements. | C8: REQ-020 REQ-022 | D8: Partial | E8: REQ-020 corrected to Pass 2026-09-24 (see Requirements sheet). Only REQ-022's activity-limits gap on conditional approval keeps this from a full Pass. | G8: =IF(AND(D8="Pass",E8<>"",F8<>""),"Verified","Unverified")
A9: AC04 | B9: All application and administrative paths refuse decision edits and deletions. Superseding is demonstrated as the correction path. A seeded privileged-storage alteration is detected by independent integrity verification and approval processing is blocked for the affected scope. | C9: REQ-019 REQ-023 REQ-025 REQ-026 REQ-027 | D9: Pass | E9: REQ-019/023/025/026/027 all Pass -- decision edit/delete is refused at the DB-role level, provenance preserved, integrity failures block acknowledgement | G9: =IF(AND(D9="Pass",E9<>"",F9<>""),"Verified","Unverified")
A10: AC05 | B10: A tenant exports the complete governance record and re-imports it into a clean instance with no loss. | C10: REQ-030 REQ-031 REQ-053 | D10: Pass | E10: REQ-030/031/053 all Pass -- lossless export/import with provenance, self-service export, and scanned attachments all real and tested | G10: =IF(AND(D10="Pass",E10<>"",F10<>""),"Verified","Unverified")
A11: AC06 | B11: WCAG 2.2 AA checks pass with no open Level A or AA failure. | C11: REQ-040 REQ-050 | D11: Not tested | E11: Neither REQ-040 (WCAG 2.2 AA audit) nor REQ-050 (penetration test) has been performed | G11: =IF(AND(D11="Pass",E11<>"",F11<>""),"Verified","Unverified")
A12: AC07 | B12: Restore into a clean environment completes within eight hours and meets the ordinary-data RPO. Fault-injection tests across the approved failure envelope demonstrate no acknowledged decision loss and successful reconstruction of the associated manifests, attribution and template versions. | C12: REQ-028 REQ-029 | D12: Not tested | E12: REQ-028's zero-loss-within-envelope claim is unproven (no approved envelope exists, DEC05 open); REQ-029's restore drill ran with real numbers but is explicitly local-prototype-only | G12: =IF(AND(D12="Pass",E12<>"",F12<>""),"Verified","Unverified")
A13: AC08 | B13: A tenant authors a custom template through the guided path — without editing JSON — and runs a project through it end to end. | C13: REQ-012 | D13: Partial | E13: REQ-012's guided-authoring UI (UI08) has no frontend page yet -- fork/import/blank-creation exist only as backend endpoints | G13: =IF(AND(D13="Pass",E13<>"",F13<>""),"Verified","Unverified")
A14: AC09 | B14: Across three different frameworks, the approved rule vocabulary produces the expected applicability, authority and blocker outcomes. Unsupported rules and attempts to weaken platform invariants are rejected. | C14: REQ-010 REQ-012 REQ-013 REQ-014 | D14: Partial | E14: REQ-010/013/014 pass; REQ-012's guided-authoring UI gap (same as AC08) keeps this from a full Pass | G14: =IF(AND(D14="Pass",E14<>"",F14<>""),"Verified","Unverified")
A15: AC10 | B15: A change to evidence or authority during approval causes the stale attempt to be refused. Repeating a committed request with the same idempotency key produces one decision. Later material changes flag reassessment without rewriting history. | C15: REQ-017 REQ-019 REQ-021 REQ-023 REQ-024 | D15: Pass | E15: REQ-017/019/021/023 pass; REQ-024 corrected and fixed 2026-09-25 (see Requirements sheet) -- all now Pass. | G15: =IF(AND(D15="Pass",E15<>"",F15<>""),"Verified","Unverified")
A16: AC11 | B16: Removing a required evidence reference cannot leave an item Complete. Unapproved exclusions, expired exceptions and conditional approval without a deadline are refused; legitimate exclusions remain visible separately in the dashboard. | C16: REQ-017 REQ-018 REQ-020 REQ-021 REQ-022 | D16: Partial | E16: REQ-017/018/020/021 all Pass (REQ-020 corrected 2026-09-24, see Requirements sheet). Only REQ-022's activity-limits gap keeps this from a full Pass. | G16: =IF(AND(D16="Pass",E16<>"",F16<>""),"Verified","Unverified")
A17: AC12 | B17: Two routine and one triggered Project Gate 5 occurrences retain distinct evidence snapshots and outcomes. Superseding a decision in one occurrence preserves all other history. | C17: REQ-016 REQ-025 | D17: Pass | E17: REQ-016/025 both Pass -- gate_occurrences represents each review as its own row; superseding is reason-recorded and never mutates the original | G17: =IF(AND(D17="Pass",E17<>"",F17<>""),"Verified","Unverified")
... A28: AC23 | B28: Deadlines and decision times are unambiguous across the tested time zones. If practice projects or reminders are delivered, practice decisions stay out of live reports and completed tasks stop generating routine reminders. | C28: REQ-039 REQ-054 REQ-055 | D28: Not tested | E28: REQ-039 (timezone/translation), REQ-054 (reminders) and REQ-055 (practice mode) are all Not tested/not built | G28: =IF(AND(D28="Pass",E28<>"",F28<>""),"Verified","Unverified")

Sheet Work packages
A2: Work packages — Blueprint v0.2 Approved
A5: ID | B5: Work package | C5: Dependencies | D5: Responsible role | E5: Review point | F5: Deliverable | G5: Status | H5: Assigned person | I5: Due date | J5: Evidence | K5: Reviewer | L5: Closure
A6: WP01 | B6: Repository and delivery controls | C6: None | D6: Delivery lead | E6: Local foundation | F6: Controlled repository, build instructions, synthetic fixtures, requirement ledger | G6: Complete | H6: Freston Kenny Adedeme | J6: commit f00ddfc; backend/requirements.txt, alembic.ini, .github/workflows/ci.yml, fixtures/synthetic/ | L6: =IF(AND(G6="Complete",H6<>"",J6<>"",K6<>""),"Recorded complete","Open")
A7: WP02 | B7: Discovery and assurance decisions | C7: WP01 | D7: Sponsor and reviewers | E7: G1 and G2 baselines | F7: Market, roles, data inventory, assurance plan, privacy and threat reviews | G7: In progress | H7: Freston Kenny Adedeme | J7: docs/wp02/ (5 documents, 2026-09-16): threat_model_and_privacy_assessment.md and data_inventory_and_classification.md are Submitted for review; assurance_plan.md and data_retention_policy.md stay In progress -- no approved Sponsor/budget exists yet to fill them in honestly. | L7: =IF(AND(G7="Complete",H7<>"",J7<>"",K7<>""),"Recorded complete","Open")
A8: WP03 | B8: Identity and membership | C8: WP01 | D8: Backend lead | E8: Local prototype then G2 baseline | F8: Registration, sessions, MFA, invitations, project permissions | G8: Complete | H8: Freston Kenny Adedeme | J8: commit deb3969 (2026-09-16, local prototype); MFA hardened via BGP-F01 fix (b1fb402, 2026-09-17) and BGP-F01 follow-up fix (b8bb22a, PR#3, 2026-09-19) | K8: MiltonBello15 (PR#3 MFA-hardening fix only, not the original build -- APPROVED, checked via gh pr view) | L8: =IF(AND(G8="Complete",H8<>"",J8<>"",K8<>""),"Recorded complete","Open")
A9: WP04 | B9: Tenant isolation | C9: WP03 | D9: Backend lead | E9: Local prototype then independent verification | F9: RLS migrations, restricted roles, pooled-session and worker isolation tests | G9: Complete | H9: Freston Kenny Adedeme | J9: RLS migrations 0002/0014; test_tenant_isolation_rls.py adversarial cross-tenant suite (REQ-009) passing against real Postgres; org-bootstrap RLS ordering bug fixed PR#4 (ac7f0f1) | K9: MiltonBello15 (PR#4 org-bootstrap fix only -- APPROVED, checked via gh pr view) | L9: =IF(AND(G9="Complete",H9<>"",J9<>"",K9<>""),"Recorded complete","Open")
A10: WP05 | B10: Templates and rule interpreter | C10: WP01 WP02 | D10: Backend lead | E10: Local prototype then G2 baseline | F10: Three framework fixtures, rule schema, immutable publication, guided authoring contract | G10: Complete | H10: Freston Kenny Adedeme | J10: commit 94b6c92 (2026-09-16); app/rule_engine.py, templates router (create/fork/import/publish), 3 synthetic framework fixtures. Guided-authoring UI (UI08) not yet built at the frontend layer -- tracked as IPA02, open. | L10: =IF(AND(G10="Complete",H10<>"",J10<>"",K10<>""),"Recorded complete","Open")
A11: WP06 | B11: Projects and evidence revisions | C11: WP04 WP05 | D11: Backend lead | E11: After design review | F11: Atomic project seeding, evidence history, recurring occurrences | G11: Complete | H11: Freston Kenny Adedeme | J11: WP06 build (2026-09-16); projects/evidence_items/evidence_revisions tables; test_seeding_failure_leaves_no_project_row proves atomicity (REQ-015) | L11: =IF(AND(G11="Complete",H11<>"",J11<>"",K11<>""),"Recorded complete","Open")
A12: WP07 | B12: Decisions and exceptions | C12: WP06 WP03 | D12: Backend lead | E12: After design review | F12: Atomic revision checks, scoped exceptions, append-only decisions | G12: Complete | H12: Freston Kenny Adedeme | J12: WP07 build (2026-09-16) + BGP-F02/F03 fixes (b1fb402) + follow-up fixes (b8bb22a, PR#3): decision_records SELECT+INSERT-only DB-role grant, authenticated compensating review, evidence-row and membership-row locking | K12: MiltonBello15 (PR#3 concurrency/separation-of-duties fixes only -- APPROVED, checked via gh pr view) | L12: =IF(AND(G12="Complete",H12<>"",J12<>"",K12<>""),"Recorded complete","Open")
A13: WP08 | B13: Integrity and recovery | C13: WP07 WP02 | D13: Security and operations lead | E13: After durability ADR | F13: Independent verification path, fault tests, restore drill | G13: Complete | H13: Freston Kenny Adedeme | J13: WP08 build (2026-09-17); integrity_checkpoints hash chain; backend/scripts/restore_drill.py actually run against live bgp_dev (backup 1.18s / restore 4.14s / 16-table reconciliation); bgp_owner superuser bug found and fixed same session | L13: =IF(AND(G13="Complete",H13<>"",J13<>"",K13<>""),"Recorded complete","Open")
A14: WP09 | B14: Export and import | C14: WP06 WP07 | D14: Backend lead | E14: After export schema review | F14: Versioned archive, permission-safe import, round-trip reconciliation | G14: Complete | H14: Freston Kenny Adedeme | J14: WP09 build (2026-09-17) + BGP-F04 fix (b1fb402) + follow-up fix (b8bb22a, PR#3): source_id provenance, full revision-history export, unmatched-author/timestamp preservation on re-export. Export/import UI (UI09) not yet built -- tracked as IPA02, open. | K14: MiltonBello15 (PR#3 provenance fix only -- APPROVED, checked via gh pr view) | L14: =IF(AND(G14="Complete",H14<>"",J14<>"",K14<>""),"Recorded complete","Open")
A15: WP10 | B15: Essential user journeys | C15: WP03 WP06 WP07 | D15: Frontend lead | E15: Prototype now; integrated after dependencies | F15: My work, guided forms, saves, blockers, decision summary | G15: Complete | H15: Freston Kenny Adedeme | J15: Backend built 2026-09-17 (My work, guided forms, drafts, blockers, decision summary); frontend delivered under TRACKER.md's 'WP11'/'WP13' headings, 2026-09-20 -- see docs/wp_identifier_mapping.md for the real cross-reference to this WP number | L15: =IF(AND(G15="Complete",H15<>"",J15<>"",K15<>""),"Recorded complete","Open")
A16: WP11 | B16: Usability and accessibility | C16: WP10 | D16: UX and QA lead | E16: Formative now; acceptance before release | F16: Participant protocol, accessible journey results, remediation evidence | G16: Not started | J16: No participant usability/accessibility testing protocol has been run. TRACKER.md's own 'WP11' heading is a DIFFERENT thing (frontend build, mapped to Blueprint WP10 above) -- see docs/wp_identifier_mapping.md. REQ-040/041/042 (WCAG 2.2 AA, 20-minute onboarding, no critical misunderstanding) remain unverified against real participants. | L16: =IF(AND(G16="Complete",H16<>"",J16<>"",K16<>""),"Recorded complete","Open")
A17: WP12 | B17: Operations and hardening | C17: WP04 WP08 | D17: Operations lead | E17: Before external pilot | F17: Secrets, monitoring, vulnerability handling, performance and recovery readiness | G17: In progress | H17: Freston Kenny Adedeme | J17: WP12 build (2026-09-17): session-key/MFA-secret encryption, pip-audit+gitleaks wired into CI (14 real vulnerabilities found and fixed same session), security_log_events table, telemetry middleware. REQ-043's numeric performance budget stays DEC08-gated; REQ-046's vuln-disclosure SLA and REQ-047's quarterly access-review are mechanisms only, not running processes yet. | L17: =IF(AND(G17="Complete",H17<>"",J17<>"",K17<>""),"Recorded complete","Open")
A18: WP13 | B18: Independent acceptance and release | C18: WP09 WP11 WP12 | D18: Release authority and independent QA | E18: Project Gate 4 / Software G4 | F18: Penetration test, user acceptance, release and rollback records | G18: Not started | J18: No penetration test, no formal user-acceptance record, no release/rollback record exists. TRACKER.md's own 'WP13' heading is a DIFFERENT thing (frontend pages, mapped to Blueprint WP10 above) -- see docs/wp_identifier_mapping.md. Tracked as IPA04 in BGP_Implementation_Plan_Alignment_Findings_v1.0.docx, explicitly release-blocking. | L18: =IF(AND(G18="Complete",H18<>"",J18<>"",K18<>""),"Recorded complete","Open")
A19: WP14 | B19: Optional and paid capabilities | C19: WP07 WP09 WP10 | D19: Product and engineering leads | E19: Separate scope decision | F19: Attachments, reminders, practice and billing; no paid signup before billing acceptance | G19: In progress | H19: Freston Kenny Adedeme | J19: Attachments (REQ-053) delivered under TRACKER.md's 'WP15' heading (2026-09-21): evidence_attachments table, real Cloudmersive scanning, undownloadable-until-clean gate -- see docs/wp_identifier_mapping.md. Reminders (REQ-054), practice mode (REQ-055) and billing (REQ-056) are not built. | L19: =IF(AND(G19="Complete",H19<>"",J19<>"",K19<>""),"Recorded complete","Open")

Sheet Remediation
A2: Remediation — Blueprint v0.2 Approved
A5: ID | B5: Finding | C5: Requirements | D5: Packages | E5: Result | F5: Evidence reference | G5: Reviewer | H5: Verification | I5: Assigned owner
A6: TR01 | B6: Open routes and missing tenancy | C6: REQ-001 REQ-002 REQ-003 REQ-004 REQ-007 REQ-008 | D6: WP03 WP04 | E6: Pass | F6: WP03 (deb3969) + WP04 RLS migrations (0002, 0014); test_tenant_isolation_rls.py adversarial cross-tenant suite (REQ-009) passing against real Postgres; full suite 153/153 (2026-09-24). | H6: =IF(AND(E6="Pass",F6<>"",G6<>""),"Verified","Unverified")
A7: TR02 | B7: Overwritten decisions and typed authority | C7: REQ-016 REQ-023 REQ-025 | D7: WP06 WP07 | E7: Pass | F7: WP07: decision_records is a SELECT+INSERT-only DB-role grant (not just route-level), proved by test_wp07_tenant_isolation_rls.py (UPDATE/DELETE raise permission denied); superseding endpoint never mutates the original row, always creates a new linked record. | H7: =IF(AND(E7="Pass",F7<>"",G7<>""),"Verified","Unverified")
A8: TR03 | B8: Unverified exclusions | C8: REQ-020 REQ-021 | D8: WP07 | E8: Pass | F8: REQ-021 (live authority/scope/expiry re-check) and REQ-020 (typed-status-alone cannot exclude an item) are both real: see REQ-020/REQ-021 rows in the Requirements sheet for the full evidence trail, including 2 new tests added 2026-09-24 to close a genuine test-coverage gap (live-expiry-over-time, cross-item scoping) that the original TR03 pass had not verified. | H8: =IF(AND(E8="Pass",F8<>"",G8<>""),"Verified","Unverified")
A9: TR04 | B9: Incomplete conditional approval checks | C9: REQ-022 | D9: WP07 | E9: Partial (activity-limits gap open) | F9: WP07 records and requires conditions before a conditional approval, but REQ-022's 'activity limits' on what a conditionally-approved project can then do are not enforced -- an open gap named in the WP07 build notes since 2026-09-16, still true 2026-09-24. | H9: =IF(AND(E9="Pass",F9<>"",G9<>""),"Verified","Unverified")
A10: TR05 | B10: Evidence reference can be cleared | C10: REQ-018 | D10: WP06 | E10: Pass | F10: app/routers/projects.py's evidence-revision validation rejects status=Complete + required + no-reference (WP06, 2026-09-16) -- an evidence reference cannot be cleared while marked Complete and required. | H10: =IF(AND(E10="Pass",F10<>"",G10<>""),"Verified","Unverified")
A11: TR06 | B11: Inconsistent HTML and Markdown controls | C11: REQ-016 REQ-022 REQ-037 | D11: WP06 WP07 WP10 | E11: Not tested | F11: No specific check has been made of HTML/Markdown control consistency across evidence, decision and summary displays. Not claimed fixed for lack of evidence. | H11: =IF(AND(E11="Pass",F11<>"",G11<>""),"Verified","Unverified")
A12: TR07 | B12: Prototype database and delivery foundation | C12: REQ-007 REQ-029 REQ-049 | D12: WP01 WP04 WP08 | E12: Partial (foundation tested, still a single-instance prototype) | F12: WP08's restore_drill.py actually run against live bgp_dev (backup 1.18s / restore 4.14s / 16-table reconciliation, 2026-09-17); migrations 0001-0016 applied cleanly; code review is now real (BGP-HR-001, PRs 3-7). Still a single local Postgres instance, not production infrastructure -- same limitation as DEC05/IPA04, not resolved by this finding closing. | H12: =IF(AND(E12="Pass",F12<>"",G12<>""),"Verified","Unverified")

Sheet Decisions
A2: Decisions — Blueprint v0.2 Approved
A5: ID | B5: Decision needed | C5: Responsible role | D5: Needed by | E5: Current position | F5: Status | G5: Named owner | H5: Decision record | I5: Approval date
A6: DEC01 | B6: Named delivery lead and independent reviewer | C6: Sponsor | D6: Before relying on their authority | E6: Delivery lead and independent reviewer named and accepted (see Named owner). Independent reviewer has since submitted real APPROVED GitHub reviews on PR#3/#4/#5, not just accepted the appointment on paper. | F6: Decided | G6: Delivery lead: Freston Kenny Adedeme. Independent reviewer: MiltonBello15 -- an active GitHub collaborator who has since submitted real APPROVED reviews on PR#3, PR#4 and PR#5, checked via gh pr view, not just named on paper. | H6: APR-001; Blueprint v0.2 Sections 7 and 9; user approval in conversation | I6: 46280
A7: DEC02 | B7: Market, region and residency | C7: Sponsor and privacy reviewer | D7: Project Gate 2 / Software G1 | E7: Approved initial focus on small agencies and consultancies. Geography, hosting region and residency remain to be selected. | F7: Partly decided | H7: APR-001; Blueprint v0.2 Sections 7 and 9; user approval in conversation | I7: 46280
A8: DEC03 | B8: Template and platform licensing | C8: Owner | D8: Project Gate 2 / Software G1 | E8: Approved licensing-clearance requirement and neutral-starter fallback. No licence or third-party permission is granted by this approval. | F8: Partly decided | H8: APR-001; Blueprint v0.2 Sections 7 and 9; user approval in conversation | I8: 46280
A9: DEC04 | B9: Frontend and API session architecture | C9: Technical lead | D9: Project Gate 3 / Software G2 | E9: Selected 2026-09-20: server-rendered FastAPI+Jinja2, same-origin, existing signed-cookie session (no SPA, no separate build step). Pinned versions tracked in backend/requirements.txt and docs/dependency_licence_inventory.md. | F9: Decided | G9: Freston Kenny Adedeme (in-session architecture decision, 2026-09-20): server-rendered FastAPI+Jinja2, same-origin, existing signed-cookie session -- no SPA, no separate build step. | H9: APR-001; Blueprint v0.2 Sections 7 and 9; user approval in conversation | I9: 46285
A10: DEC05 | B10: Durability failure envelope and mechanism | C10: Operations and security leads | D10: Project Gate 3 / Software G2 | E10: Decided 2026-09-27 (kenAddme's supplied answer, accepted by the delivery lead -- not an independent Operations/security-leads sign-off): Candidate A+ -- neither original candidate as framed, a synthesis of synchronous durable replication before acknowledgement (clean, truthful 'Recorded' response) plus an asynchronous independently-protected hash-chain anchor for tamper-evidence; Candidate B's pending-and-reconcile pattern survives only as a labelled, alerting degraded fallback when the sync replica is unavailable, never counted as a recorded decision. Failure scenarios covered: process crash, node failure, storage failure, single-zone failure (zero acknowledged-decision loss); regional failure via continuous archiving to a second region (RPO<=5min, restored inside RTO). Explicitly NOT covered by durability alone: logical corruption from a code defect or an authorised-but-malicious write (detected by the hash chain, recovered by point-in-time restore, not prevented by replication), and simultaneous loss of the primary region and its archive. Integrity-verification mechanism is independent: the chain anchor writes to object-lock (WORM) storage under a credential the application database role cannot overwrite/delete; verification runs under a third, separate identity. Numeric targets: availability 99.5% monthly; RPO 0 in-region, <=5min cross-region; RTO 8 hours; quarterly restore test into a clean environment; integrity verification at least daily, a chain mismatch treated as an S1 incident acknowledged within 1 hour. Acknowledgement is synchronous: the API returns success only once the decision row, audit entry and chain link are committed in one transaction and confirmed on a same-region different-zone synchronous replica. FLAGGED, NOT SETTLED BY THIS ANSWER ALONE: Candidate A+ is a synthesis not offered as an option in the original intake framing -- Operations/security leads still need to confirm what they are actually being asked to approve, since it isn't literally 'A or B.' | F10: Decided | G10: Named owner assigned 2026-09-25: kenAddme (active GitHub collaborator, real APPROVED reviews on PR#5/#6/#7, checked via gh pr view). Responsible for driving this decision to actual resolution -- this is an OWNERSHIP ASSIGNMENT ONLY, not the decision itself: Candidate A vs. Candidate B, covered failure scenarios, and custody for DEC05's durability mechanism remains unspecified until kenAddme (or whoever actually holds the role: Operations and security leads) supplies it. Status/Decision record/Approval date deliberately left untouched -- do not read this cell as the decision having been made. kenAddme's substantive answer received 2026-09-25/27 (docs/blueprint/BGP_DEC_Resolution_Intake_2026-09-25_ANSWERED.md) and accepted by the delivery lead in conversation 2026-09-27 -- still not an independent Operations/security-leads sign-off. The answer document itself flags the Candidate A+ framing as needing explicit confirmation at review -- see 'Open items' in the answered doc. | H10: APR-001; Blueprint v0.2 Sections 7 and 9; user approval in conversation; docs/blueprint/BGP_DEC_Resolution_Intake_2026-09-25_ANSWERED.md (accepted 2026-09-27) | I10: 46292
A11: DEC06 | B11: Retention, disposal and attribution | C11: Privacy reviewer and owner | D11: Before retention implementation | E11: Decided 2026-09-27 (kenAddme's supplied answer, accepted by the delivery lead -- not an independent Privacy-reviewer/owner sign-off): retention periods differ by record type as a floor tenants may lengthen but not shorten -- decisions/gate approvals/exceptions 7yrs after Gate 6; requirements/designs/acceptance/release records life-of-service+3yrs (never <7yrs after Gate 6); audit events 7yrs after Gate 6 or after the event, whichever is later; attachment bytes shortest of all, default 3yrs, tenant-configurable, purgeable early while metadata/hash survive. REQ-025's permanent-record guarantee narrowed to structural fields only (actor id, timestamp, action, before/after hashes in decisions/gate_decisions/audit_events -- never mutable); redaction permitted only on named personal-data fields and attachment bytes, implemented as a chain-re-anchored redaction event (proves a redaction happened without revealing what was redacted) -- one narrow, genuine exception, not a blanket one. Actor stored as a stable pseudonymous id with the id-to-person mapping in one separately-redactable table so an erasure request doesn't break a chain. True end-of-retention disposal removes the row set and leaves a tombstone (record id, hash, disposal date, authoriser, method). Legal hold: placed by the tenant's named records custodian/data owner or the project sponsor (platform operator only on written legal instruction, tenant notified it exists); overrides all scheduled disposal/shortening/purge but not a legally compelled erasure request (routed to legal advice instead). Mandatory hold fields: scope/reason/owner/placed date/release condition; release needs the same role and its own record. Other specifics: deleted users keep attribution via stable id + display-name snapshot; exports pseudonymous by default; disposal effective in live data within 24h, in backups within the backup retention window (no false instant-deletion claim). | F11: Decided | G11: Named owner assigned 2026-09-25: kenAddme (active GitHub collaborator, real APPROVED reviews on PR#5/#6/#7, checked via gh pr view). Responsible for driving this decision to actual resolution -- this is an OWNERSHIP ASSIGNMENT ONLY, not the decision itself: actual retention periods and the permanent-record conflict for DEC06 remains unspecified until kenAddme (or whoever actually holds the role: Privacy reviewer and owner) supplies it. Status/Decision record/Approval date deliberately left untouched -- do not read this cell as the decision having been made. kenAddme's substantive answer received 2026-09-25/27 (docs/blueprint/BGP_DEC_Resolution_Intake_2026-09-25_ANSWERED.md) and accepted by the delivery lead in conversation 2026-09-27 -- still not an independent Privacy-reviewer/owner sign-off. | H11: APR-001; Blueprint v0.2 Sections 7 and 9; user approval in conversation; docs/blueprint/BGP_DEC_Resolution_Intake_2026-09-25_ANSWERED.md (accepted 2026-09-27) | I11: 46292
A12: DEC07 | B12: Rule vocabulary and three frameworks | C12: Technical lead | D12: Before guided authoring implementation | E12: Decided 2026-09-27 (kenAddme's supplied answer, accepted by the delivery lead -- not an independent Technical-lead sign-off): current vocabulary (eq/in/all/any, depth 5, no eval/exec) approved as-is, plus additions -- not (negation), gte/lte (dates/counts), count(...) with a comparison ('at least N of these complete') -- and two tightenings: cap total condition nodes at 200 in addition to depth-5, and a hard evaluation timeout; rules are pure functions of project state plus a supplied 'as at' timestamp (no external calls, no wall-clock reads inside a rule). vocabulary_version stamped on every template version so old templates evaluate identically forever. Third permitted framework fixture: an agile Definition-of-Ready/Definition-of-Done framework with no gates at all (recurring per-increment checks, unnumbered, evaluated every sprint) -- deliberately the harder, structurally-different test; second choice if an external standard is preferred: NIST SSDF 800-218 practice groups. Scope: full parity with the other two fixtures (tracks/items/rules/roles/statuses/decisions) -- marked a validation fixture, not a shipped starter template, until it passes its own review. | F12: Decided | G12: Named owner assigned 2026-09-25: kenAddme (active GitHub collaborator, real APPROVED reviews on PR#5/#6/#7, checked via gh pr view). Responsible for driving this decision to actual resolution -- this is an OWNERSHIP ASSIGNMENT ONLY, not the decision itself: vocabulary limits and the third permitted framework for DEC07 remains unspecified until kenAddme (or whoever actually holds the role: Technical lead) supplies it. Status/Decision record/Approval date deliberately left untouched -- do not read this cell as the decision having been made. kenAddme's substantive answer received 2026-09-25/27 (docs/blueprint/BGP_DEC_Resolution_Intake_2026-09-25_ANSWERED.md) and accepted by the delivery lead in conversation 2026-09-27 -- still not an independent Technical-lead sign-off. | H12: APR-001; Blueprint v0.2 Sections 7 and 9; user approval in conversation; docs/blueprint/BGP_DEC_Resolution_Intake_2026-09-25_ANSWERED.md (accepted 2026-09-27) | I12: 46292
A13: DEC08 | B13: Usability sample and performance budgets | C13: UX and technical leads | D13: G1 protocol; G2 technical budgets | E13: Decided 2026-09-27 (kenAddme's supplied answer, accepted by the delivery lead -- not an independent UX/technical-leads sign-off): sample sizes -- beginner 8, contributor 5, client approver 5, administrator 5 (23 total); disabled/assistive-technology users distributed across the four groups (>=5 total) plus a dedicated expert accessibility review, not a separate fifth group; >=6 participants on older/low-end devices, similarly distributed. Device/network profiles: primary budget target mid-range Android on Fast 3G (1.6Mbps/150ms RTT, the realistic Ghanaian mobile case); degraded acceptance case low-end Android (~4GB RAM, 2019-era) on Slow 3G (400kbps/400ms RTT), which must stay usable not fast; also an iPhone 2-3 generations old on 4G, desktop broadband baseline, 320px/360px viewports, 400% zoom reflow (WCAG 1.4.10). API p95 latency budgets (server time at origin): reads (gate view/dashboard) p95<=300ms/p99<=800ms; ordinary writes p95<=500ms; decision writes p95<=800ms/p99<=1.5s (the allowance DEC05's synchronous replica commit needs); exports asynchronous, must begin streaming within 2s. Page/render budget: critical render path <=170KB compressed; total first load <=350KB, heaviest authoring screen <=1MB; LCP<=2.5s primary/<=5s degraded; INP<=200ms; CLS<=0.1; no more than two blocking requests before first render -- all enforced in CI as a blocking budget check, not a dashboard someone reads occasionally. | F13: Decided | G13: Named owner assigned 2026-09-25: kenAddme (active GitHub collaborator, real APPROVED reviews on PR#5/#6/#7, checked via gh pr view). Responsible for driving this decision to actual resolution -- this is an OWNERSHIP ASSIGNMENT ONLY, not the decision itself: sample sizes, device/network profiles and numeric performance budgets for DEC08 remains unspecified until kenAddme (or whoever actually holds the role: UX and technical leads) supplies it. Status/Decision record/Approval date deliberately left untouched -- do not read this cell as the decision having been made. kenAddme's substantive answer received 2026-09-25/27 (docs/blueprint/BGP_DEC_Resolution_Intake_2026-09-25_ANSWERED.md) and accepted by the delivery lead in conversation 2026-09-27 -- still not an independent UX/technical-leads sign-off. | H13: APR-001; Blueprint v0.2 Sections 7 and 9; user approval in conversation; docs/blueprint/BGP_DEC_Resolution_Intake_2026-09-25_ANSWERED.md (accepted 2026-09-27) | I13: 46292
A14: DEC09 | B14: Budget, capacity and delivery estimate | C14: Sponsor | D14: Before scope extension or external commitment | E14: Approved work-package sequence and responsibility roles. Actual staffing, funding, estimates and dates remain to be supplied; no spending commitment is created. | F14: Partly decided | H14: APR-001; Blueprint v0.2 Sections 7 and 9; user approval in conversation | I14: 46280
A15: DEC10 | B15: Payment, free-tier and grace policy | C15: Sponsor | D15: Before paid capabilities | E15: Approved payment controls and no-card-data boundary. Processor, tier limits and grace periods remain to be selected before paid use. | F15: Partly decided | H15: APR-001; Blueprint v0.2 Sections 7 and 9; user approval in conversation | I15: 46280
